Workbook

Sheet Dashboard
A1: Music app - where we are
A2: Everything here is calculated from the Roadmap sheet. Do not type in the grey cells.
A4: Overall progress
A5: Tasks done | B5: =COUNTIF(Roadmap!E5:E66,"☑")
A6: Tasks in total | B6: =COUNTA(Roadmap!C5:C66)
A7: Complete | B7: =IF(B6=0,0,B5/B6)
A8: Waiting on you | B8: =COUNTIF(Roadmap!F5:F66,"Needs you")
A9: Marked Next | B9: =COUNTIF(Roadmap!F5:F66,"Next")
A11: Phase | B11: Phase name | C11: Done | D11: Total | E11: Progress | F11: Status
A12: 0 | B12: Foundation | C12: =COUNTIFS(Roadmap!$A$5:$A$66,A12,Roadmap!$E$5:$E$66,"☑") | D12: =COUNTIF(Roadmap!$A$5:$A$66,A12) | E12: =IF(D12=0,0,C12/D12) | F12: =IF(C12=D12,"Finished",IF(C12=0,"Not started","In progress"))
A13: 1 | B13: Release pipeline | C13: =COUNTIFS(Roadmap!$A$5:$A$66,A13,Roadmap!$E$5:$E$66,"☑") | D13: =COUNTIF(Roadmap!$A$5:$A$66,A13) | E13: =IF(D13=0,0,C13/D13) | F13: =IF(C13=D13,"Finished",IF(C13=0,"Not started","In progress"))
A14: 2 | B14: Schema + metadata | C14: =COUNTIFS(Roadmap!$A$5:$A$66,A14,Roadmap!$E$5:$E$66,"☑") | D14: =COUNTIF(Roadmap!$A$5:$A$66,A14) | E14: =IF(D14=0,0,C14/D14) | F14: =IF(C14=D14,"Finished",IF(C14=0,"Not started","In progress"))
A15: 3 | B15: ZIP upload (admin) | C15: =COUNTIFS(Roadmap!$A$5:$A$66,A15,Roadmap!$E$5:$E$66,"☑") | D15: =COUNTIF(Roadmap!$A$5:$A$66,A15) | E15: =IF(D15=0,0,C15/D15) | F15: =IF(C15=D15,"Finished",IF(C15=0,"Not started","In progress"))
A16: 4 | B16: Classification + review | C16: =COUNTIFS(Roadmap!$A$5:$A$66,A16,Roadmap!$E$5:$E$66,"☑") | D16: =COUNTIF(Roadmap!$A$5:$A$66,A16) | E16: =IF(D16=0,0,C16/D16) | F16: =IF(C16=D16,"Finished",IF(C16=0,"Not started","In progress"))
A17: 5 | B17: Discovery | C17: =COUNTIFS(Roadmap!$A$5:$A$66,A17,Roadmap!$E$5:$E$66,"☑") | D17: =COUNTIF(Roadmap!$A$5:$A$66,A17) | E17: =IF(D17=0,0,C17/D17) | F17: =IF(C17=D17,"Finished",IF(C17=0,"Not started","In progress"))
A18: 6 | B18: Player upgrades | C18: =COUNTIFS(Roadmap!$A$5:$A$66,A18,Roadmap!$E$5:$E$66,"☑") | D18: =COUNTIF(Roadmap!$A$5:$A$66,A18) | E18: =IF(D18=0,0,C18/D18) | F18: =IF(C18=D18,"Finished",IF(C18=0,"Not started","In progress"))
A19: 7 | B19: Offline downloads | C19: =COUNTIFS(Roadmap!$A$5:$A$66,A19,Roadmap!$E$5:$E$66,"☑") | D19: =COUNTIF(Roadmap!$A$5:$A$66,A19) | E19: =IF(D19=0,0,C19/D19) | F19: =IF(C19=D19,"Finished",IF(C19=0,"Not started","In progress"))
A20: 8 | B20: Offline mode | C20: =COUNTIFS(Roadmap!$A$5:$A$66,A20,Roadmap!$E$5:$E$66,"☑") | D20: =COUNTIF(Roadmap!$A$5:$A$66,A20) | E20: =IF(D20=0,0,C20/D20) | F20: =IF(C20=D20,"Finished",IF(C20=0,"Not started","In progress"))
A21: 9 | B21: In-app updater | C21: =COUNTIFS(Roadmap!$A$5:$A$66,A21,Roadmap!$E$5:$E$66,"☑") | D21: =COUNTIF(Roadmap!$A$5:$A$66,A21) | E21: =IF(D21=0,0,C21/D21) | F21: =IF(C21=D21,"Finished",IF(C21=0,"Not started","In progress"))
A22: 10 | B22: Admin deployment | C22: =COUNTIFS(Roadmap!$A$5:$A$66,A22,Roadmap!$E$5:$E$66,"☑") | D22: =COUNTIF(Roadmap!$A$5:$A$66,A22) | E22: =IF(D22=0,0,C22/D22) | F22: =IF(C22=D22,"Finished",IF(C22=0,"Not started","In progress"))
A23: 11 | B23: Quality + security | C23: =COUNTIFS(Roadmap!$A$5:$A$66,A23,Roadmap!$E$5:$E$66,"☑") | D23: =COUNTIF(Roadmap!$A$5:$A$66,A23) | E23: =IF(D23=0,0,C23/D23) | F23: =IF(C23=D23,"Finished",IF(C23=0,"Not started","In progress"))
A24: 12 | B24: Future ideas | C24: =COUNTIFS(Roadmap!$A$5:$A$66,A24,Roadmap!$E$5:$E$66,"☑") | D24: =COUNTIF(Roadmap!$A$5:$A$66,A24) | E24: =IF(D24=0,0,C24/D24) | F24: =IF(C24=D24,"Finished",IF(C24=0,"Not started","In progress"))
A26: Current phase (first one not finished): | C26: =INDEX(B12:B24,MATCH(TRUE,INDEX(C12:C24<D12:D24,0),0))
A28: Note: phases are numbered as in docs/PLAN.md (1-11), plus 0 = foundation and 12 = future ideas. Several phases run in parallel, so 'current phase' is just the earliest one with open tasks.

Sheet Roadmap
A1: Music app - roadmap and checklist
A2: Click a cell in the Done column and pick ☑ (done) or ☐ (not done). Progress and the dashboard update by themselves.
A4: Phase | B4: Phase name | C4: Task | D4: Area | E4: Done | F4: When | G4: Notes
A5: 0 | B5: Foundation | C5: Express + TypeScript API with JWT login (15 min access / 30 day refresh) | D5: Backend | E5: ☑ | F5: Done
A6: 0 | B6: Foundation | C6: PostgreSQL on Aiven (users, songs, artists, albums, genres, playlists, likes, recently played) | D6: Backend | E6: ☑ | F6: Done
A7: 0 | B7: Foundation | C7: Cloudflare R2 storage at media.deploymentportal.in | D7: Backend | E7: ☑ | F7: Done
A8: 0 | B8: Foundation | C8: Backend deployed on Render free plan | D8: Backend | E8: ☑ | F8: Done | G8: Sleeps when idle; first request can take about a minute
A9: 0 | B9: Foundation | C9: Website on Cloudflare Pages (music.deploymentportal.in) | D9: Web | E9: ☑ | F9: Done
A10: 0 | B10: Foundation | C10: Android app: player, playlists, likes, search, account page, logout | D10: Mobile | E10: ☑ | F10: Done
A11: 0 | B11: Foundation | C11: Google sign-in on the website | D11: Web | E11: ☑ | F11: Done
A12: 0 | B12: Foundation | C12: Google sign-in in the Android app | D12: Mobile | E12: ☐ | F12: Later | G12: Needs Android OAuth client + SHA-1 of the signing key (do after the private key)
A13: 0 | B13: Foundation | C13: Loading spinners, skip 5 s, app icon, direct APK download button on the website | D13: All | E13: ☑ | F13: Done
A14: 1 | B14: Release pipeline | C14: GitHub Actions build on tag vX.Y.Z or manual run | D14: CI | E14: ☑ | F14: Done
A15: 1 | B15: Release pipeline | C15: Version taken from the tag (versionName / versionCode) | D15: CI | E15: ☑ | F15: Done
A16: 1 | B16: Release pipeline | C16: Emulator launch test with strict crash detection | D16: CI | E16: ☑ | F16: Done
A17: 1 | B17: Release pipeline | C17: Publish music.apk + version.json to the 'latest' release; keep last good APK on failure | D17: CI | E17: ☑ | F17: Done
A18: 1 | B18: Release pipeline | C18: Private release signing key stored in GitHub Secrets (replaces committed debug key) | D18: CI | E18: ☐ | F18: Needs you | G18: Decide before sharing the app widely - one reinstall needed (risk R1)
A19: 2 | B19: Schema + metadata | C19: Movie fields on albums; song soundtrack fields; draft/published status | D19: Backend | E19: ☑ | F19: Done
A20: 2 | B20: Schema + metadata | C20: Labels (style / mood / genre), upload jobs and job items tables | D20: Backend | E20: ☑ | F20: Done
A21: 2 | B21: Schema + metadata | C21: Telugu reference workbook import (49 artists, 36 draft movies, genres) | D21: Backend | E21: ☑ | F21: Done | G21: npm run import:reference - safe to repeat
A22: 3 | B22: ZIP upload (admin) | C22: Safe streaming ZIP upload (size, count, extension, path and magic-byte checks) | D22: Backend | E22: ☑ | F22: Done
A23: 3 | B23: ZIP upload (admin) | C23: Movie-name detection from typed name or ZIP name; duplicate and vague-name checks | D23: Backend | E23: ☑ | F23: Done
A24: 3 | B24: ZIP upload (admin) | C24: Rights confirmation required; songs created as drafts; per-file job progress | D24: Backend | E24: ☑ | F24: Done
A25: 3 | B25: ZIP upload (admin) | C25: Admin upload screen with name confirmation flow | D25: Admin | E25: ☑ | F25: Done
A26: 4 | B26: Classification + review | C26: Audio analysis (tempo, loudness, brightness, beat strength) with confidence scores | D26: Backend | E26: ☑ | F26: Done | G26: Rule-based heuristic-v1, not a trained model
A27: 4 | B27: Classification + review | C27: Admin review screen: approve / reject / edit / re-run, bulk approve | D27: Admin | E27: ☑ | F27: Done
A28: 4 | B28: Classification + review | C28: Smart search using approved labels only (AND across labels and languages) | D28: Backend | E28: ☑ | F28: Done
A29: 4 | B29: Classification + review | C29: Optional external classifier service (CLASSIFIER_URL) | D29: Backend | E29: ☑ | F29: Done
A30: 4 | B30: Classification + review | C30: Train a real model on licensed, labelled audio (ml/train.py) | D30: ML | E30: ☐ | F30: Optional | G30: Needs a labelled dataset we do not have
A31: 5 | B31: Discovery | C31: Jamendo (Creative Commons) search and import to R2 | D31: Backend | E31: ☑ | F31: Done
A32: 5 | B32: Discovery | C32: YouTube search, play-only in the official embedded player | D32: All | E32: ☑ | F32: Done
A33: 5 | B33: Discovery | C33: Trending + popular Telugu videos on the website | D33: Web | E33: ☑ | F33: Done
A34: 5 | B34: Discovery | C34: Trending + popular Telugu videos in the Android app | D34: Mobile | E34: ☑ | F34: Done | G34: Published in v0.2.2 / v0.2.3; not yet checked on a phone
A35: 5 | B35: Discovery | C35: Movie pages, label browser and combined search on the website | D35: Web | E35: ☑ | F35: Done
A36: 5 | B36: Discovery | C36: Android: movie list and movie page screens | D36: Mobile | E36: ☐ | F36: Next
A37: 5 | B37: Discovery | C37: Android: label browser (Melody + Romantic etc.) and new search | D37: Mobile | E37: ☐ | F37: Next
A38: 5 | B38: Discovery | C38: Show workbook tags / example singers on movie pages | D38: Web | E38: ☐ | F38: Later
A39: 5 | B39: Discovery | C39: Archive.org / Spotify embed as extra legal sources | D39: Backend | E39: ☐ | F39: Optional
A40: 6 | B40: Player upgrades | C40: Repeat one / all and shuffle | D40: Mobile | E40: ☐ | F40: Later
A41: 6 | B41: Player upgrades | C41: Queue screen (view, reorder, remove) | D41: Mobile | E41: ☐ | F41: Later
...

Sheet Architecture
A1: Architecture - what talks to what
A3: Component | B3: Technology | C3: Hosted on | D3: Address / location | E3: Talks to | F3: Purpose | G3: Cost
A4: Android app | B4: React Native 0.87 + TypeScript, Zustand, TanStack Query, react-native-track-player, WebView | C4: Phone (APK from GitHub release) | D4: mobile/ | E4: Backend API, R2 (audio), YouTube player | F4: Listening, playlists, likes, trending videos | G4: Free
A5: Website | B5: React + Vite + TypeScript | C5: Cloudflare Pages | D5: music.deploymentportal.in (web/) | E5: Backend API, R2, YouTube player, Google sign-in | F5: Listening in a browser; Download-app button | G5: Free
A6: Admin panel | B6: React + Vite + TypeScript | C6: Your laptop now; Cloudflare Pages planned | D6: admin/ | E6: Backend API (/admin/...) | F6: ZIP upload, review labels, publish, mark downloadable | G6: Free
A7: Backend API | B7: Node + Express + TypeScript, zod, JWT, bcryptjs, multer, yauzl, music-metadata, bundled ffmpeg | C7: Render (free plan) | D7: musicapp-j5ji.onrender.com (backend/) | E7: PostgreSQL, R2, Google, YouTube, Jamendo | F7: All business logic, auth, search, uploads, classification | G7: Free (sleeps when idle)
A8: Database | B8: PostgreSQL | C8: Aiven (free plan, SSL) | D8: backend/db/schema.sql | E8: Backend only | F8: Users, songs, movies, labels, playlists, upload jobs, classifications | G8: Free
A9: File storage | B9: Cloudflare R2 (S3 API) | C9: Cloudflare | D9: media.deploymentportal.in | E9: Backend writes; apps read audio and covers | F9: Audio files, covers, posters | G9: Free tier
A10: Build pipeline | B10: GitHub Actions | C10: GitHub | D10: .github/workflows/android.yml | E10: GitHub release 'latest' | F10: Build, sign, emulator test, publish APK + version.json | G10: Free
A11: Google sign-in | B11: Google Identity / google-auth-library | C11: Google | D11: Google Cloud project | E11: Website, backend | F11: Sign in with Google | G11: Free
A12: YouTube Data API | B12: REST | C12: Google | D12: Key stored on Render | E12: Backend | F12: Search and trending Telugu videos (played only in YouTube's own player) | G12: Free quota
A13: Jamendo API | B13: REST | C13: Jamendo | D13: Key stored on Render | E13: Backend | F13: Creative Commons music search and import | G13: Free
A14: Classifier | B14: Local rules over ffmpeg audio features (heuristic-v1); optional external service via CLASSIFIER_URL | C14: Inside the backend | D14: backend/src/classifier/ | E14: Backend, R2 audio | F14: Suggested labels with confidence for admin review | G14: Free
A16: Main flows
A17: Listening | B17: App / website -> Backend (list, search) -> PostgreSQL; audio streamed straight from R2
A18: Admin upload | B18: Admin panel -> Backend (stream ZIP) -> checks -> songs saved to R2 as DRAFT -> classify -> admin approves labels -> publish
A19: Discovery | B19: App / website -> Backend -> YouTube / Jamendo; Jamendo imports are copied to R2; YouTube only plays in the embedded player
A20: Release | B20: Tag vX.Y.Z -> GitHub Actions build + sign + emulator test -> release 'latest' (music.apk, version.json) -> website Download button
A21: Download a song | B21: App -> Backend (only if songs.downloadable) -> short-lived signed link -> R2

Sheet API routes
A1: Backend route map
A2: Built = live now. Planned = needed by a later phase.
A3: Group | B3: Method | C3: Path | D3: Who | E3: Purpose | F3: Status
A4: Health | B4: GET | C4: /health | D4: Anyone | E4: Server and integration status | F4: Built
A5: Auth | B5: POST | C5: /auth/register, /auth/login, /auth/refresh, /auth/google | D5: Anyone | E5: Create account, sign in, renew token, Google sign-in | F5: Built
A6: Songs | B6: GET | C6: /songs (sort, labels, language, q, limit, offset) | D6: Anyone | E6: List and filter published songs | F6: Built
A7: Songs | B7: GET | C7: /songs/search?q= | D7: Anyone | E7: Smart search; label searches use approved labels only | F7: Built
A8: Songs | B8: POST/DELETE | C8: /songs/:id/like | D8: User | E8: Like / unlike | F8: Built
A9: Songs | B9: GET | C9: /songs/:id/download-link, /songs/:id/download | D9: User | E9: Signed download, only if downloadable | F9: Built
A10: Catalogue | B10: GET | C10: /artists, /artists/:id/songs, /albums, /albums/:id/songs, /genres | D10: Anyone | E10: Browse | F10: Built
A11: Movies | B11: GET | C11: /movies, /movies/:id | D11: Anyone | E11: Published movie soundtracks | F11: Built
A12: Labels | B12: GET | C12: /moods | D12: Anyone | E12: Label list with counts of approved labels | F12: Built
A13: Playlists | B13: GET/POST/PUT/DELETE | C13: /playlists, /playlists/:id, /playlists/:id/songs | D13: User | E13: Manage playlists | F13: Built
A14: Me | B14: GET | C14: /users/me/recently-played, /users/me/liked-songs | D14: User | E14: Personal lists | F14: Built
... A25: Admin analytics | B25: GET | C25: /admin/stats | D25: Admin | E25: Plays, top songs | F25: Planned (future)

Sheet Screens
A1: Screen map - app vs website
A2: ☑ built, ☐ not built
A3: Screen | B3: Website | C3: Android app | D3: Admin panel | E3: Notes
A4: Login / register / Google | B4: ☑ | C4: ☑ (Google not yet) | D4: ☑
A5: Home (recent, popular, artists) | B5: ☑ | C5: ☑ | D5: -
A6: Trending + popular Telugu videos | B6: ☑ | C6: ☑ | D6: - | E6: YouTube embedded player
A7: Search (library, Jamendo, YouTube) | B7: ☑ | C7: ☑ | D7: -
A8: Smart label search / label browser | B8: ☑ | C8: ☐ | D8: - | E8: Phase 5
A9: Movie list and movie page | B9: ☑ | C9: ☐ | D9: - | E9: Phase 5
A10: Now playing | B10: ☑ | C10: ☑ | D10: -
A11: Queue | B11: ☐ | C11: ☐ | D11: - | E11: Phase 6
A12: Playlists and liked songs | B12: ☑ | C12: ☑ | D12: -
A13: Account / logout | B13: ☑ | C13: ☑ | D13: -
A14: Download app button | B14: ☑ | C14: - | D14: -
A15: Downloads (offline) | B15: ☐ | C15: ☐ | D15: - | E15: Phases 7-8
A16: Update available prompt | B16: - | C16: ☐ | D16: - | E16: Phase 9
A17: ZIP upload with movie-name detection | B17: - | C17: - | D17: ☑
A18: Movies list, review labels, publish | B18: - | C18: - | D18: ☑ | E18: Needs deployment (phase 10)

Sheet Options
A1: Choices and decisions
A3: Option | B3: What it gives | C3: Effort | D3: Catch | E3: Recommendation
A4: A. Android movies + labels screens | B4: App matches the website | C4: Medium | D4: No new native code | E4: Do next
A5: B. Deploy admin to Cloudflare Pages | B5: Upload from any device | C5: Small | D5: One setup step by you | E5: Do soon
A6: C. Private signing key | B6: Safe updates for other users | C6: Small | D6: Needs keytool; one reinstall | E6: Do before sharing widely
A7: D. Offline downloads + offline mode | B7: Listen without internet | C7: Large | D7: Native library; must test on a phone | E7: After A
A8: E. In-app updater | B8: Update from inside the app | C8: Medium | D8: Android still shows its confirm prompt | E8: After C
A9: F. Player upgrades | B9: Repeat, queue, recovery | C9: Medium | D9: - | E9: Any time
A10: G. Train a real classifier | B10: Better label suggestions | C10: Large | D10: Needs licensed, labelled audio | E10: Only if you have data
A11: H. App locker (separate app) | B11: Lock other apps with fingerprint + PIN | C11: Large | D11: Accessibility permission; phone-brand battery quirks | E11: Your decision
A12: Render paid plan / keep-alive | B12: No sleeping server | C12: Small | D12: Paid, or pings | E12: Optional

Sheet Rules
A1: Rules we keep
A3: YouTube is played only in its own visible embedded player. No downloading, no audio extraction, no hidden player.
A4: Songs can be downloaded only when the admin marks them downloadable and has the rights.
A5: No music imported from sites without a licence.
A6: Uploads need a rights confirmation and arrive as drafts; nothing is public until published.
A7: Search uses only labels an admin has approved.
A8: Secrets live in Render and GitHub settings only - never in the app, repo or chat.
A9: The APK is built only when asked (tag vX.Y.Z or manual run). Takes about 18-25 minutes.
